        <!-- <param name="spring_description" command="$(find xacro)/xacro --inorder $(find dual_manipulation_control)/urdf/spring.urdf.xacro" /> -->
        <!-- <node name="molla_spawner" pkg="gazebo_ros" type="spawn_model" args="-param spring_description -urdf -model spring -x -0.8 -y -0.15 -z 3.15 -R 0 -P 0 -Y 0" respawn="false" output="screen"/> -->

<?xml version="1.0" ?>

<!-- <robot xmlns:xacro="http://www.ros.org/wiki/xacro" name="spring"> -->

<sdf version="1.4">
  <model name="spring">
    <pose>0.0 1.5 0.6  0 0 0</pose>
    <link name="spring">

      <inertial>
        <inertia>
          <ixx>0.01</ixx>
          <ixy>0.0</ixy>
          <ixz>0.0</ixz>
          <iyy>0.01</iyy>
          <iyz>0.0</iyz>
          <izz>0.01</izz>
        </inertia>
        <mass>1.0</mass>
      </inertial>

      <visual name="visual">
        <geometry>
          <cylinder>
            <length>0.1</length>
            <radius>0.1</radius>
          </cylinder>
        </geometry>
        <material>
          <script><uri>file://media/materials/scripts/gazebo.material</uri><name>Gazebo/Green</name></script>
        </material>
      </visual>

      <collision name="collision">
        <geometry>
          <cylinder>
            <length>0.1</length>
            <radius>0.1</radius>7
          </cylinder>
        </geometry>
      </collision>

    </link>
    <joint name="joint" type="prismatic">
      <parent>world</parent>
      <child>spring</child>
      <pose>0.0 0.0 0.5  0 0 0</pose>
      <axis>

        <limit>
          <lower>-1.0</lower>
          <upper>1.0</upper>
        </limit>

        <xyz>0.0 0.0 1.0</xyz>

        <dynamics>
          <spring_stiffness>111.1111</spring_stiffness>
          <spring_reference>0.0</spring_reference>
          <damping>0.0</damping>
          <friction>0.0</friction>
        </dynamics>

      </axis>
    </joint>
  </model>
</sdf>